[2024-11-25T14:58:42.753+0000] {local_task_job_runner.py:123} INFO - ::group::Pre task execution logs
[2024-11-25T14:58:42.779+0000] {taskinstance.py:2613} INFO - Dependencies all met for dep_context=non-requeueable deps ti=<TaskInstance: weather_data_pipeline.collect_data scheduled__2024-04-10T00:00:00+00:00 [queued]>
[2024-11-25T14:58:42.798+0000] {taskinstance.py:2613} INFO - Dependencies all met for dep_context=requeueable deps ti=<TaskInstance: weather_data_pipeline.collect_data scheduled__2024-04-10T00:00:00+00:00 [queued]>
[2024-11-25T14:58:42.799+0000] {taskinstance.py:2866} INFO - Starting attempt 1 of 1
[2024-11-25T14:58:42.852+0000] {taskinstance.py:2889} INFO - Executing <Task(BashOperator): collect_data> on 2024-04-10 00:00:00+00:00
[2024-11-25T14:58:42.860+0000] {standard_task_runner.py:72} INFO - Started process 904 to run task
[2024-11-25T14:58:42.867+0000] {standard_task_runner.py:104} INFO - Running: ['airflow', 'tasks', 'run', 'weather_data_pipeline', 'collect_data', 'scheduled__2024-04-10T00:00:00+00:00', '--job-id', '106', '--raw', '--subdir', 'DAGS_FOLDER/weather_pipeline.py', '--cfg-path', '/tmp/tmpurpc_aej']
[2024-11-25T14:58:42.871+0000] {standard_task_runner.py:105} INFO - Job 106: Subtask collect_data
[2024-11-25T14:58:43.023+0000] {task_command.py:467} INFO - Running <TaskInstance: weather_data_pipeline.collect_data scheduled__2024-04-10T00:00:00+00:00 [running]> on host fc3583ec8965
[2024-11-25T14:58:43.274+0000] {taskinstance.py:3132} INFO - Exporting env vars: AIRFLOW_CTX_DAG_OWNER='airflow' AIRFLOW_CTX_DAG_ID='weather_data_pipeline' AIRFLOW_CTX_TASK_ID='collect_data' AIRFLOW_CTX_EXECUTION_DATE='2024-04-10T00:00:00+00:00' AIRFLOW_CTX_TRY_NUMBER='1' AIRFLOW_CTX_DAG_RUN_ID='scheduled__2024-04-10T00:00:00+00:00'
[2024-11-25T14:58:43.276+0000] {taskinstance.py:731} INFO - ::endgroup::
[2024-11-25T14:58:43.301+0000] {subprocess.py:78} INFO - Tmp dir root location: /tmp
[2024-11-25T14:58:43.303+0000] {subprocess.py:88} INFO - Running command: ['/usr/bin/bash', '-c', 'python /opt/airflow/data_collection.py']
[2024-11-25T14:58:43.316+0000] {subprocess.py:99} INFO - Output:
[2024-11-25T14:58:43.363+0000] {subprocess.py:106} INFO - python: can't open file '/opt/airflow/data_collection.py': [Errno 2] No such file or directory
[2024-11-25T14:58:43.367+0000] {subprocess.py:110} INFO - Command exited with return code 2
[2024-11-25T14:58:43.386+0000] {taskinstance.py:3311} ERROR - Task failed with exception
Traceback (most recent call last):
  File "/home/airflow/.local/lib/python3.12/site-packages/airflow/models/taskinstance.py", line 767, in _execute_task
    result = _execute_callable(context=context, **execute_callable_kwargs)
             ^^^^^^^^^^^^^^^^^^^^^^^^^^^^^^^^^^^^^^^^^^^^^^^^^^^^^^^^^^^^^
  File "/home/airflow/.local/lib/python3.12/site-packages/airflow/models/taskinstance.py", line 733, in _execute_callable
    return ExecutionCallableRunner(
           ^^^^^^^^^^^^^^^^^^^^^^^^
  File "/home/airflow/.local/lib/python3.12/site-packages/airflow/utils/operator_helpers.py", line 252, in run
    return self.func(*args, **kwargs)
           ^^^^^^^^^^^^^^^^^^^^^^^^^^
  File "/home/airflow/.local/lib/python3.12/site-packages/airflow/models/baseoperator.py", line 417, in wrapper
    return func(self, *args, **kwargs)
           ^^^^^^^^^^^^^^^^^^^^^^^^^^^
  File "/home/airflow/.local/lib/python3.12/site-packages/airflow/operators/bash.py", line 276, in execute
    raise AirflowException(
airflow.exceptions.AirflowException: Bash command failed. The command returned a non-zero exit code 2.
[2024-11-25T14:58:43.394+0000] {taskinstance.py:1225} INFO - Marking task as FAILED. dag_id=weather_data_pipeline, task_id=collect_data, run_id=scheduled__2024-04-10T00:00:00+00:00, execution_date=20240410T000000, start_date=20241125T145842, end_date=20241125T145843
[2024-11-25T14:58:43.444+0000] {taskinstance.py:340} INFO - ::group::Post task execution logs
[2024-11-25T14:58:43.445+0000] {standard_task_runner.py:124} ERROR - Failed to execute job 106 for task collect_data (Bash command failed. The command returned a non-zero exit code 2.; 904)
Traceback (most recent call last):
  File "/home/airflow/.local/lib/python3.12/site-packages/airflow/task/task_runner/standard_task_runner.py", line 117, in _start_by_fork
    ret = args.func(args, dag=self.dag)
          ^^^^^^^^^^^^^^^^^^^^^^^^^^^^^
  File "/home/airflow/.local/lib/python3.12/site-packages/airflow/cli/cli_config.py", line 49, in command
    return func(*args, **kwargs)
           ^^^^^^^^^^^^^^^^^^^^^
  File "/home/airflow/.local/lib/python3.12/site-packages/airflow/utils/cli.py", line 116, in wrapper
    return f(*args, **kwargs)
           ^^^^^^^^^^^^^^^^^^
  File "/home/airflow/.local/lib/python3.12/site-packages/airflow/cli/commands/task_command.py", line 483, in task_run
    task_return_code = _run_task_by_selected_method(args, _dag, ti)
                       ^^^^^^^^^^^^^^^^^^^^^^^^^^^^^^^^^^^^^^^^^^^^
  File "/home/airflow/.local/lib/python3.12/site-packages/airflow/cli/commands/task_command.py", line 256, in _run_task_by_selected_method
    return _run_raw_task(args, ti)
           ^^^^^^^^^^^^^^^^^^^^^^^
  File "/home/airflow/.local/lib/python3.12/site-packages/airflow/cli/commands/task_command.py", line 341, in _run_raw_task
    return ti._run_raw_task(
           ^^^^^^^^^^^^^^^^^
  File "/home/airflow/.local/lib/python3.12/site-packages/airflow/utils/session.py", line 97, in wrapper
    return func(*args, session=session, **kwargs)
           ^^^^^^^^^^^^^^^^^^^^^^^^^^^^^^^^^^^^^^
  File "/home/airflow/.local/lib/python3.12/site-packages/airflow/models/taskinstance.py", line 3005, in _run_raw_task
    return _run_raw_task(
           ^^^^^^^^^^^^^^
  File "/home/airflow/.local/lib/python3.12/site-packages/airflow/models/taskinstance.py", line 273, in _run_raw_task
    TaskInstance._execute_task_with_callbacks(
  File "/home/airflow/.local/lib/python3.12/site-packages/airflow/models/taskinstance.py", line 3159, in _execute_task_with_callbacks
    result = self._execute_task(context, task_orig)
             ^^^^^^^^^^^^^^^^^^^^^^^^^^^^^^^^^^^^^^
  File "/home/airflow/.local/lib/python3.12/site-packages/airflow/models/taskinstance.py", line 3183, in _execute_task
    return _execute_task(self, context, task_orig)
           ^^^^^^^^^^^^^^^^^^^^^^^^^^^^^^^^^^^^^^^
  File "/home/airflow/.local/lib/python3.12/site-packages/airflow/models/taskinstance.py", line 767, in _execute_task
    result = _execute_callable(context=context, **execute_callable_kwargs)
             ^^^^^^^^^^^^^^^^^^^^^^^^^^^^^^^^^^^^^^^^^^^^^^^^^^^^^^^^^^^^^
  File "/home/airflow/.local/lib/python3.12/site-packages/airflow/models/taskinstance.py", line 733, in _execute_callable
    return ExecutionCallableRunner(
           ^^^^^^^^^^^^^^^^^^^^^^^^
  File "/home/airflow/.local/lib/python3.12/site-packages/airflow/utils/operator_helpers.py", line 252, in run
    return self.func(*args, **kwargs)
           ^^^^^^^^^^^^^^^^^^^^^^^^^^
  File "/home/airflow/.local/lib/python3.12/site-packages/airflow/models/baseoperator.py", line 417, in wrapper
    return func(self, *args, **kwargs)
           ^^^^^^^^^^^^^^^^^^^^^^^^^^^
  File "/home/airflow/.local/lib/python3.12/site-packages/airflow/operators/bash.py", line 276, in execute
    raise AirflowException(
airflow.exceptions.AirflowException: Bash command failed. The command returned a non-zero exit code 2.
[2024-11-25T14:58:43.485+0000] {local_task_job_runner.py:266} INFO - Task exited with return code 1
[2024-11-25T14:58:43.523+0000] {taskinstance.py:3895} INFO - 0 downstream tasks scheduled from follow-on schedule check
[2024-11-25T14:58:43.556+0000] {local_task_job_runner.py:245} INFO - ::endgroup::
