[2024-11-25T15:36:33.863+0000] {local_task_job_runner.py:123} INFO - ::group::Pre task execution logs
[2024-11-25T15:36:33.892+0000] {taskinstance.py:2613} INFO - Dependencies all met for dep_context=non-requeueable deps ti=<TaskInstance: weather_data_pipeline.collect_data manual__2024-11-25T15:36:17.739484+00:00 [queued]>
[2024-11-25T15:36:33.914+0000] {taskinstance.py:2613} INFO - Dependencies all met for dep_context=requeueable deps ti=<TaskInstance: weather_data_pipeline.collect_data manual__2024-11-25T15:36:17.739484+00:00 [queued]>
[2024-11-25T15:36:33.916+0000] {taskinstance.py:2866} INFO - Starting attempt 1 of 1
[2024-11-25T15:36:33.964+0000] {taskinstance.py:2889} INFO - Executing <Task(BashOperator): collect_data> on 2024-11-25 15:36:17.739484+00:00
[2024-11-25T15:36:33.972+0000] {standard_task_runner.py:72} INFO - Started process 127 to run task
[2024-11-25T15:36:33.977+0000] {standard_task_runner.py:104} INFO - Running: ['airflow', 'tasks', 'run', 'weather_data_pipeline', 'collect_data', 'manual__2024-11-25T15:36:17.739484+00:00', '--job-id', '148', '--raw', '--subdir', 'DAGS_FOLDER/weather_pipeline.py', '--cfg-path', '/tmp/tmpqzjrb1hy']
[2024-11-25T15:36:33.981+0000] {standard_task_runner.py:105} INFO - Job 148: Subtask collect_data
[2024-11-25T15:36:34.097+0000] {task_command.py:467} INFO - Running <TaskInstance: weather_data_pipeline.collect_data manual__2024-11-25T15:36:17.739484+00:00 [running]> on host 39c0c8829bcb
[2024-11-25T15:36:34.262+0000] {taskinstance.py:3132} INFO - Exporting env vars: AIRFLOW_CTX_DAG_OWNER='airflow' AIRFLOW_CTX_DAG_ID='weather_data_pipeline' AIRFLOW_CTX_TASK_ID='collect_data' AIRFLOW_CTX_EXECUTION_DATE='2024-11-25T15:36:17.739484+00:00' AIRFLOW_CTX_TRY_NUMBER='1' AIRFLOW_CTX_DAG_RUN_ID='manual__2024-11-25T15:36:17.739484+00:00'
[2024-11-25T15:36:34.264+0000] {taskinstance.py:731} INFO - ::endgroup::
[2024-11-25T15:36:34.293+0000] {subprocess.py:78} INFO - Tmp dir root location: /tmp
[2024-11-25T15:36:34.295+0000] {subprocess.py:88} INFO - Running command: ['/usr/bin/bash', '-c', 'python /opt/airflow/data_collection.py']
[2024-11-25T15:36:34.310+0000] {subprocess.py:99} INFO - Output:
[2024-11-25T15:36:34.376+0000] {subprocess.py:106} INFO - python: can't open file '/opt/airflow/data_collection.py': [Errno 2] No such file or directory
[2024-11-25T15:36:34.381+0000] {subprocess.py:110} INFO - Command exited with return code 2
[2024-11-25T15:36:34.424+0000] {taskinstance.py:3311} ERROR - Task failed with exception
Traceback (most recent call last):
  File "/home/airflow/.local/lib/python3.12/site-packages/airflow/models/taskinstance.py", line 767, in _execute_task
    result = _execute_callable(context=context, **execute_callable_kwargs)
             ^^^^^^^^^^^^^^^^^^^^^^^^^^^^^^^^^^^^^^^^^^^^^^^^^^^^^^^^^^^^^
  File "/home/airflow/.local/lib/python3.12/site-packages/airflow/models/taskinstance.py", line 733, in _execute_callable
    return ExecutionCallableRunner(
           ^^^^^^^^^^^^^^^^^^^^^^^^
  File "/home/airflow/.local/lib/python3.12/site-packages/airflow/utils/operator_helpers.py", line 252, in run
    return self.func(*args, **kwargs)
           ^^^^^^^^^^^^^^^^^^^^^^^^^^
  File "/home/airflow/.local/lib/python3.12/site-packages/airflow/models/baseoperator.py", line 417, in wrapper
    return func(self, *args, **kwargs)
           ^^^^^^^^^^^^^^^^^^^^^^^^^^^
  File "/home/airflow/.local/lib/python3.12/site-packages/airflow/operators/bash.py", line 276, in execute
    raise AirflowException(
airflow.exceptions.AirflowException: Bash command failed. The command returned a non-zero exit code 2.
[2024-11-25T15:36:34.432+0000] {taskinstance.py:1225} INFO - Marking task as FAILED. dag_id=weather_data_pipeline, task_id=collect_data, run_id=manual__2024-11-25T15:36:17.739484+00:00, execution_date=20241125T153617, start_date=20241125T153633, end_date=20241125T153634
[2024-11-25T15:36:34.478+0000] {taskinstance.py:340} INFO - ::group::Post task execution logs
[2024-11-25T15:36:34.479+0000] {standard_task_runner.py:124} ERROR - Failed to execute job 148 for task collect_data (Bash command failed. The command returned a non-zero exit code 2.; 127)
Traceback (most recent call last):
  File "/home/airflow/.local/lib/python3.12/site-packages/airflow/task/task_runner/standard_task_runner.py", line 117, in _start_by_fork
    ret = args.func(args, dag=self.dag)
          ^^^^^^^^^^^^^^^^^^^^^^^^^^^^^
  File "/home/airflow/.local/lib/python3.12/site-packages/airflow/cli/cli_config.py", line 49, in command
    return func(*args, **kwargs)
           ^^^^^^^^^^^^^^^^^^^^^
  File "/home/airflow/.local/lib/python3.12/site-packages/airflow/utils/cli.py", line 116, in wrapper
    return f(*args, **kwargs)
           ^^^^^^^^^^^^^^^^^^
  File "/home/airflow/.local/lib/python3.12/site-packages/airflow/cli/commands/task_command.py", line 483, in task_run
    task_return_code = _run_task_by_selected_method(args, _dag, ti)
                       ^^^^^^^^^^^^^^^^^^^^^^^^^^^^^^^^^^^^^^^^^^^^
  File "/home/airflow/.local/lib/python3.12/site-packages/airflow/cli/commands/task_command.py", line 256, in _run_task_by_selected_method
    return _run_raw_task(args, ti)
           ^^^^^^^^^^^^^^^^^^^^^^^
  File "/home/airflow/.local/lib/python3.12/site-packages/airflow/cli/commands/task_command.py", line 341, in _run_raw_task
    return ti._run_raw_task(
           ^^^^^^^^^^^^^^^^^
  File "/home/airflow/.local/lib/python3.12/site-packages/airflow/utils/session.py", line 97, in wrapper
    return func(*args, session=session, **kwargs)
           ^^^^^^^^^^^^^^^^^^^^^^^^^^^^^^^^^^^^^^
  File "/home/airflow/.local/lib/python3.12/site-packages/airflow/models/taskinstance.py", line 3005, in _run_raw_task
    return _run_raw_task(
           ^^^^^^^^^^^^^^
  File "/home/airflow/.local/lib/python3.12/site-packages/airflow/models/taskinstance.py", line 273, in _run_raw_task
    TaskInstance._execute_task_with_callbacks(
  File "/home/airflow/.local/lib/python3.12/site-packages/airflow/models/taskinstance.py", line 3159, in _execute_task_with_callbacks
    result = self._execute_task(context, task_orig)
             ^^^^^^^^^^^^^^^^^^^^^^^^^^^^^^^^^^^^^^
  File "/home/airflow/.local/lib/python3.12/site-packages/airflow/models/taskinstance.py", line 3183, in _execute_task
    return _execute_task(self, context, task_orig)
           ^^^^^^^^^^^^^^^^^^^^^^^^^^^^^^^^^^^^^^^
  File "/home/airflow/.local/lib/python3.12/site-packages/airflow/models/taskinstance.py", line 767, in _execute_task
    result = _execute_callable(context=context, **execute_callable_kwargs)
             ^^^^^^^^^^^^^^^^^^^^^^^^^^^^^^^^^^^^^^^^^^^^^^^^^^^^^^^^^^^^^
  File "/home/airflow/.local/lib/python3.12/site-packages/airflow/models/taskinstance.py", line 733, in _execute_callable
    return ExecutionCallableRunner(
           ^^^^^^^^^^^^^^^^^^^^^^^^
  File "/home/airflow/.local/lib/python3.12/site-packages/airflow/utils/operator_helpers.py", line 252, in run
    return self.func(*args, **kwargs)
           ^^^^^^^^^^^^^^^^^^^^^^^^^^
  File "/home/airflow/.local/lib/python3.12/site-packages/airflow/models/baseoperator.py", line 417, in wrapper
    return func(self, *args, **kwargs)
           ^^^^^^^^^^^^^^^^^^^^^^^^^^^
  File "/home/airflow/.local/lib/python3.12/site-packages/airflow/operators/bash.py", line 276, in execute
    raise AirflowException(
airflow.exceptions.AirflowException: Bash command failed. The command returned a non-zero exit code 2.
[2024-11-25T15:36:34.513+0000] {local_task_job_runner.py:266} INFO - Task exited with return code 1
[2024-11-25T15:36:34.555+0000] {taskinstance.py:3895} INFO - 0 downstream tasks scheduled from follow-on schedule check
[2024-11-25T15:36:34.586+0000] {local_task_job_runner.py:245} INFO - ::endgroup::
